{
 "cells": [
  {
   "cell_type": "code",
   "execution_count": 2,
   "metadata": {},
   "outputs": [
    {
     "name": "stdout",
     "output_type": "stream",
     "text": [
      "Defaulting to user installation because normal site-packages is not writeable\n",
      "Requirement already satisfied: numpy in /Users/usui/Library/Python/3.9/lib/python/site-packages (1.23.4)\n",
      "\n",
      "\u001b[1m[\u001b[0m\u001b[34;49mnotice\u001b[0m\u001b[1;39;49m]\u001b[0m\u001b[39;49m A new release of pip available: \u001b[0m\u001b[31;49m22.3.1\u001b[0m\u001b[39;49m -> \u001b[0m\u001b[32;49m23.2.1\u001b[0m\n",
      "\u001b[1m[\u001b[0m\u001b[34;49mnotice\u001b[0m\u001b[1;39;49m]\u001b[0m\u001b[39;49m To update, run: \u001b[0m\u001b[32;49m/Library/Developer/CommandLineTools/usr/bin/python3 -m pip install --upgrade pip\u001b[0m\n",
      "Defaulting to user installation because normal site-packages is not writeable\n",
      "\u001b[31mERROR: Could not find a version that satisfies the requirement osgio (from versions: none)\u001b[0m\u001b[31m\n",
      "\u001b[0m\u001b[31mERROR: No matching distribution found for osgio\u001b[0m\u001b[31m\n",
      "\u001b[0m\n",
      "\u001b[1m[\u001b[0m\u001b[34;49mnotice\u001b[0m\u001b[1;39;49m]\u001b[0m\u001b[39;49m A new release of pip available: \u001b[0m\u001b[31;49m22.3.1\u001b[0m\u001b[39;49m -> \u001b[0m\u001b[32;49m23.2.1\u001b[0m\n",
      "\u001b[1m[\u001b[0m\u001b[34;49mnotice\u001b[0m\u001b[1;39;49m]\u001b[0m\u001b[39;49m To update, run: \u001b[0m\u001b[32;49m/Library/Developer/CommandLineTools/usr/bin/python3 -m pip install --upgrade pip\u001b[0m\n",
      "Defaulting to user installation because normal site-packages is not writeable\n",
      "Collecting pvl\n",
      "  Downloading pvl-1.3.2-py2.py3-none-any.whl (66 kB)\n",
      "\u001b[2K     \u001b[90m━━━━━━━━━━━━━━━━━━━━━━━━━━━━━━━━━━━━━━━━\u001b[0m \u001b[32m66.1/66.1 kB\u001b[0m \u001b[31m2.2 MB/s\u001b[0m eta \u001b[36m0:00:00\u001b[0m\n",
      "\u001b[?25hInstalling collected packages: pvl\n",
      "Successfully installed pvl-1.3.2\n",
      "\n",
      "\u001b[1m[\u001b[0m\u001b[34;49mnotice\u001b[0m\u001b[1;39;49m]\u001b[0m\u001b[39;49m A new release of pip available: \u001b[0m\u001b[31;49m22.3.1\u001b[0m\u001b[39;49m -> \u001b[0m\u001b[32;49m23.2.1\u001b[0m\n",
      "\u001b[1m[\u001b[0m\u001b[34;49mnotice\u001b[0m\u001b[1;39;49m]\u001b[0m\u001b[39;49m To update, run: \u001b[0m\u001b[32;49m/Library/Developer/CommandLineTools/usr/bin/python3 -m pip install --upgrade pip\u001b[0m\n",
      "Defaulting to user installation because normal site-packages is not writeable\n",
      "\u001b[31mERROR: Could not find a version that satisfies the requirement json (from versions: none)\u001b[0m\u001b[31m\n",
      "\u001b[0m\u001b[31mERROR: No matching distribution found for json\u001b[0m\u001b[31m\n",
      "\u001b[0m\n",
      "\u001b[1m[\u001b[0m\u001b[34;49mnotice\u001b[0m\u001b[1;39;49m]\u001b[0m\u001b[39;49m A new release of pip available: \u001b[0m\u001b[31;49m22.3.1\u001b[0m\u001b[39;49m -> \u001b[0m\u001b[32;49m23.2.1\u001b[0m\n",
      "\u001b[1m[\u001b[0m\u001b[34;49mnotice\u001b[0m\u001b[1;39;49m]\u001b[0m\u001b[39;49m To update, run: \u001b[0m\u001b[32;49m/Library/Developer/CommandLineTools/usr/bin/python3 -m pip install --upgrade pip\u001b[0m\n",
      "Defaulting to user installation because normal site-packages is not writeable\n",
      "\u001b[31mERROR: Could not find a version that satisfies the requirement collections (from versions: none)\u001b[0m\u001b[31m\n",
      "\u001b[0m\u001b[31mERROR: No matching distribution found for collections\u001b[0m\u001b[31m\n",
      "\u001b[0m\n",
      "\u001b[1m[\u001b[0m\u001b[34;49mnotice\u001b[0m\u001b[1;39;49m]\u001b[0m\u001b[39;49m A new release of pip available: \u001b[0m\u001b[31;49m22.3.1\u001b[0m\u001b[39;49m -> \u001b[0m\u001b[32;49m23.2.1\u001b[0m\n",
      "\u001b[1m[\u001b[0m\u001b[34;49mnotice\u001b[0m\u001b[1;39;49m]\u001b[0m\u001b[39;49m To update, run: \u001b[0m\u001b[32;49m/Library/Developer/CommandLineTools/usr/bin/python3 -m pip install --upgrade pip\u001b[0m\n"
     ]
    }
   ],
   "source": [
    "!pip install numpy\n",
    "!pip install pvl\n",
    "# !pip install json\n",
    "# !pip install collections"
   ]
  },
  {
   "cell_type": "code",
   "execution_count": 5,
   "metadata": {},
   "outputs": [
    {
     "name": "stdout",
     "output_type": "stream",
     "text": [
      "Defaulting to user installation because normal site-packages is not writeable\n",
      "Collecting gdal\n",
      "  Downloading GDAL-3.7.2.tar.gz (777 kB)\n",
      "\u001b[2K     \u001b[90m━━━━━━━━━━━━━━━━━━━━━━━━━━━━━━━━━━━━━━━\u001b[0m \u001b[32m777.0/777.0 kB\u001b[0m \u001b[31m7.6 MB/s\u001b[0m eta \u001b[36m0:00:00\u001b[0ma \u001b[36m0:00:01\u001b[0m\n",
      "\u001b[?25h  Preparing metadata (setup.py) ... \u001b[?25lerror\n",
      "  \u001b[1;31merror\u001b[0m: \u001b[1msubprocess-exited-with-error\u001b[0m\n",
      "  \n",
      "  \u001b[31m×\u001b[0m \u001b[32mpython setup.py egg_info\u001b[0m did not run successfully.\n",
      "  \u001b[31m│\u001b[0m exit code: \u001b[1;36m1\u001b[0m\n",
      "  \u001b[31m╰─>\u001b[0m \u001b[31m[79 lines of output]\u001b[0m\n",
      "  \u001b[31m   \u001b[0m running egg_info\n",
      "  \u001b[31m   \u001b[0m creating /private/var/folders/x3/zx_610811k5839tt6q9rrz2h0000gp/T/pip-pip-egg-info-4nmur33h/GDAL.egg-info\n",
      "  \u001b[31m   \u001b[0m writing /private/var/folders/x3/zx_610811k5839tt6q9rrz2h0000gp/T/pip-pip-egg-info-4nmur33h/GDAL.egg-info/PKG-INFO\n",
      "  \u001b[31m   \u001b[0m writing dependency_links to /private/var/folders/x3/zx_610811k5839tt6q9rrz2h0000gp/T/pip-pip-egg-info-4nmur33h/GDAL.egg-info/dependency_links.txt\n",
      "  \u001b[31m   \u001b[0m writing requirements to /private/var/folders/x3/zx_610811k5839tt6q9rrz2h0000gp/T/pip-pip-egg-info-4nmur33h/GDAL.egg-info/requires.txt\n",
      "  \u001b[31m   \u001b[0m writing top-level names to /private/var/folders/x3/zx_610811k5839tt6q9rrz2h0000gp/T/pip-pip-egg-info-4nmur33h/GDAL.egg-info/top_level.txt\n",
      "  \u001b[31m   \u001b[0m writing manifest file '/private/var/folders/x3/zx_610811k5839tt6q9rrz2h0000gp/T/pip-pip-egg-info-4nmur33h/GDAL.egg-info/SOURCES.txt'\n",
      "  \u001b[31m   \u001b[0m Traceback (most recent call last):\n",
      "  \u001b[31m   \u001b[0m   File \"/private/var/folders/x3/zx_610811k5839tt6q9rrz2h0000gp/T/pip-install-oc_73u2b/gdal_d18099b3278a46379c7a459bf1ff380e/setup.py\", line 87, in fetch_config\n",
      "  \u001b[31m   \u001b[0m     p = subprocess.Popen([command, args], stdout=subprocess.PIPE)\n",
      "  \u001b[31m   \u001b[0m   File \"/Library/Developer/CommandLineTools/Library/Frameworks/Python3.framework/Versions/3.9/lib/python3.9/subprocess.py\", line 951, in __init__\n",
      "  \u001b[31m   \u001b[0m     self._execute_child(args, executable, preexec_fn, close_fds,\n",
      "  \u001b[31m   \u001b[0m   File \"/Library/Developer/CommandLineTools/Library/Frameworks/Python3.framework/Versions/3.9/lib/python3.9/subprocess.py\", line 1821, in _execute_child\n",
      "  \u001b[31m   \u001b[0m     raise child_exception_type(errno_num, err_msg, err_filename)\n",
      "  \u001b[31m   \u001b[0m FileNotFoundError: [Errno 2] No such file or directory: 'gdal-config'\n",
      "  \u001b[31m   \u001b[0m \n",
      "  \u001b[31m   \u001b[0m During handling of the above exception, another exception occurred:\n",
      "  \u001b[31m   \u001b[0m \n",
      "  \u001b[31m   \u001b[0m Traceback (most recent call last):\n",
      "  \u001b[31m   \u001b[0m   File \"/private/var/folders/x3/zx_610811k5839tt6q9rrz2h0000gp/T/pip-install-oc_73u2b/gdal_d18099b3278a46379c7a459bf1ff380e/setup.py\", line 188, in get_gdal_config\n",
      "  \u001b[31m   \u001b[0m     return fetch_config(option, gdal_config=self.gdal_config)\n",
      "  \u001b[31m   \u001b[0m   File \"/private/var/folders/x3/zx_610811k5839tt6q9rrz2h0000gp/T/pip-install-oc_73u2b/gdal_d18099b3278a46379c7a459bf1ff380e/setup.py\", line 90, in fetch_config\n",
      "  \u001b[31m   \u001b[0m     raise gdal_config_error(e)\n",
      "  \u001b[31m   \u001b[0m __main__.gdal_config_error: [Errno 2] No such file or directory: 'gdal-config'\n",
      "  \u001b[31m   \u001b[0m \n",
      "  \u001b[31m   \u001b[0m During handling of the above exception, another exception occurred:\n",
      "  \u001b[31m   \u001b[0m \n",
      "  \u001b[31m   \u001b[0m Traceback (most recent call last):\n",
      "  \u001b[31m   \u001b[0m   File \"<string>\", line 2, in <module>\n",
      "  \u001b[31m   \u001b[0m   File \"<pip-setuptools-caller>\", line 34, in <module>\n",
      "  \u001b[31m   \u001b[0m   File \"/private/var/folders/x3/zx_610811k5839tt6q9rrz2h0000gp/T/pip-install-oc_73u2b/gdal_d18099b3278a46379c7a459bf1ff380e/setup.py\", line 350, in <module>\n",
      "  \u001b[31m   \u001b[0m     setup(\n",
      "  \u001b[31m   \u001b[0m   File \"/Library/Developer/CommandLineTools/Library/Frameworks/Python3.framework/Versions/3.9/lib/python3.9/site-packages/setuptools/__init__.py\", line 153, in setup\n",
      "  \u001b[31m   \u001b[0m     return distutils.core.setup(**attrs)\n",
      "  \u001b[31m   \u001b[0m   File \"/Library/Developer/CommandLineTools/Library/Frameworks/Python3.framework/Versions/3.9/lib/python3.9/distutils/core.py\", line 148, in setup\n",
      "  \u001b[31m   \u001b[0m     dist.run_commands()\n",
      "  \u001b[31m   \u001b[0m   File \"/Library/Developer/CommandLineTools/Library/Frameworks/Python3.framework/Versions/3.9/lib/python3.9/distutils/dist.py\", line 966, in run_commands\n",
      "  \u001b[31m   \u001b[0m     self.run_command(cmd)\n",
      "  \u001b[31m   \u001b[0m   File \"/Library/Developer/CommandLineTools/Library/Frameworks/Python3.framework/Versions/3.9/lib/python3.9/distutils/dist.py\", line 985, in run_command\n",
      "  \u001b[31m   \u001b[0m     cmd_obj.run()\n",
      "  \u001b[31m   \u001b[0m   File \"/Library/Developer/CommandLineTools/Library/Frameworks/Python3.framework/Versions/3.9/lib/python3.9/site-packages/setuptools/command/egg_info.py\", line 299, in run\n",
      "  \u001b[31m   \u001b[0m     self.find_sources()\n",
      "  \u001b[31m   \u001b[0m   File \"/Library/Developer/CommandLineTools/Library/Frameworks/Python3.framework/Versions/3.9/lib/python3.9/site-packages/setuptools/command/egg_info.py\", line 306, in find_sources\n",
      "  \u001b[31m   \u001b[0m     mm.run()\n",
      "  \u001b[31m   \u001b[0m   File \"/Library/Developer/CommandLineTools/Library/Frameworks/Python3.framework/Versions/3.9/lib/python3.9/site-packages/setuptools/command/egg_info.py\", line 541, in run\n",
      "  \u001b[31m   \u001b[0m     self.add_defaults()\n",
      "  \u001b[31m   \u001b[0m   File \"/Library/Developer/CommandLineTools/Library/Frameworks/Python3.framework/Versions/3.9/lib/python3.9/site-packages/setuptools/command/egg_info.py\", line 578, in add_defaults\n",
      "  \u001b[31m   \u001b[0m     sdist.add_defaults(self)\n",
      "  \u001b[31m   \u001b[0m   File \"/Library/Developer/CommandLineTools/Library/Frameworks/Python3.framework/Versions/3.9/lib/python3.9/distutils/command/sdist.py\", line 228, in add_defaults\n",
      "  \u001b[31m   \u001b[0m     self._add_defaults_ext()\n",
      "  \u001b[31m   \u001b[0m   File \"/Library/Developer/CommandLineTools/Library/Frameworks/Python3.framework/Versions/3.9/lib/python3.9/distutils/command/sdist.py\", line 311, in _add_defaults_ext\n",
      "  \u001b[31m   \u001b[0m     build_ext = self.get_finalized_command('build_ext')\n",
      "  \u001b[31m   \u001b[0m   File \"/Library/Developer/CommandLineTools/Library/Frameworks/Python3.framework/Versions/3.9/lib/python3.9/distutils/cmd.py\", line 299, in get_finalized_command\n",
      "  \u001b[31m   \u001b[0m     cmd_obj.ensure_finalized()\n",
      "  \u001b[31m   \u001b[0m   File \"/Library/Developer/CommandLineTools/Library/Frameworks/Python3.framework/Versions/3.9/lib/python3.9/distutils/cmd.py\", line 107, in ensure_finalized\n",
      "  \u001b[31m   \u001b[0m     self.finalize_options()\n",
      "  \u001b[31m   \u001b[0m   File \"/private/var/folders/x3/zx_610811k5839tt6q9rrz2h0000gp/T/pip-install-oc_73u2b/gdal_d18099b3278a46379c7a459bf1ff380e/setup.py\", line 255, in finalize_options\n",
      "  \u001b[31m   \u001b[0m     gdaldir = self.get_gdal_config('prefix')\n",
      "  \u001b[31m   \u001b[0m   File \"/private/var/folders/x3/zx_610811k5839tt6q9rrz2h0000gp/T/pip-install-oc_73u2b/gdal_d18099b3278a46379c7a459bf1ff380e/setup.py\", line 194, in get_gdal_config\n",
      "  \u001b[31m   \u001b[0m     raise gdal_config_error(traceback_string + '\\n' + msg)\n",
      "  \u001b[31m   \u001b[0m __main__.gdal_config_error: Traceback (most recent call last):\n",
      "  \u001b[31m   \u001b[0m   File \"/private/var/folders/x3/zx_610811k5839tt6q9rrz2h0000gp/T/pip-install-oc_73u2b/gdal_d18099b3278a46379c7a459bf1ff380e/setup.py\", line 87, in fetch_config\n",
      "  \u001b[31m   \u001b[0m     p = subprocess.Popen([command, args], stdout=subprocess.PIPE)\n",
      "  \u001b[31m   \u001b[0m   File \"/Library/Developer/CommandLineTools/Library/Frameworks/Python3.framework/Versions/3.9/lib/python3.9/subprocess.py\", line 951, in __init__\n",
      "  \u001b[31m   \u001b[0m     self._execute_child(args, executable, preexec_fn, close_fds,\n",
      "  \u001b[31m   \u001b[0m   File \"/Library/Developer/CommandLineTools/Library/Frameworks/Python3.framework/Versions/3.9/lib/python3.9/subprocess.py\", line 1821, in _execute_child\n",
      "  \u001b[31m   \u001b[0m     raise child_exception_type(errno_num, err_msg, err_filename)\n",
      "  \u001b[31m   \u001b[0m FileNotFoundError: [Errno 2] No such file or directory: 'gdal-config'\n",
      "  \u001b[31m   \u001b[0m \n",
      "  \u001b[31m   \u001b[0m During handling of the above exception, another exception occurred:\n",
      "  \u001b[31m   \u001b[0m \n",
      "  \u001b[31m   \u001b[0m Traceback (most recent call last):\n",
      "  \u001b[31m   \u001b[0m   File \"/private/var/folders/x3/zx_610811k5839tt6q9rrz2h0000gp/T/pip-install-oc_73u2b/gdal_d18099b3278a46379c7a459bf1ff380e/setup.py\", line 188, in get_gdal_config\n",
      "  \u001b[31m   \u001b[0m     return fetch_config(option, gdal_config=self.gdal_config)\n",
      "  \u001b[31m   \u001b[0m   File \"/private/var/folders/x3/zx_610811k5839tt6q9rrz2h0000gp/T/pip-install-oc_73u2b/gdal_d18099b3278a46379c7a459bf1ff380e/setup.py\", line 90, in fetch_config\n",
      "  \u001b[31m   \u001b[0m     raise gdal_config_error(e)\n",
      "  \u001b[31m   \u001b[0m gdal_config_error: [Errno 2] No such file or directory: 'gdal-config'\n",
      "  \u001b[31m   \u001b[0m \n",
      "  \u001b[31m   \u001b[0m Could not find gdal-config. Make sure you have installed the GDAL native library and development headers.\n",
      "  \u001b[31m   \u001b[0m \u001b[31m[end of output]\u001b[0m\n",
      "  \n",
      "  \u001b[1;35mnote\u001b[0m: This error originates from a subprocess, and is likely not a problem with pip.\n",
      "\u001b[?25h\u001b[1;31merror\u001b[0m: \u001b[1mmetadata-generation-failed\u001b[0m\n",
      "\n",
      "\u001b[31m×\u001b[0m Encountered error while generating package metadata.\n",
      "\u001b[31m╰─>\u001b[0m See above for output.\n",
      "\n",
      "\u001b[1;35mnote\u001b[0m: This is an issue with the package mentioned above, not pip.\n",
      "\u001b[1;36mhint\u001b[0m: See above for details.\n",
      "\n",
      "\u001b[1m[\u001b[0m\u001b[34;49mnotice\u001b[0m\u001b[1;39;49m]\u001b[0m\u001b[39;49m A new release of pip available: \u001b[0m\u001b[31;49m22.3.1\u001b[0m\u001b[39;49m -> \u001b[0m\u001b[32;49m23.2.1\u001b[0m\n",
      "\u001b[1m[\u001b[0m\u001b[34;49mnotice\u001b[0m\u001b[1;39;49m]\u001b[0m\u001b[39;49m To update, run: \u001b[0m\u001b[32;49m/Library/Developer/CommandLineTools/usr/bin/python3 -m pip install --upgrade pip\u001b[0m\n"
     ]
    }
   ],
   "source": [
    "!pip install gdal"
   ]
  },
  {
   "cell_type": "code",
   "execution_count": null,
   "metadata": {},
   "outputs": [],
   "source": [
    "# !pip install \n"
   ]
  },
  {
   "cell_type": "code",
   "execution_count": 7,
   "metadata": {},
   "outputs": [
    {
     "ename": "ModuleNotFoundError",
     "evalue": "No module named 'gdal'",
     "output_type": "error",
     "traceback": [
      "\u001b[0;31m---------------------------------------------------------------------------\u001b[0m",
      "\u001b[0;31mModuleNotFoundError\u001b[0m                       Traceback (most recent call last)",
      "\u001b[1;32m/Users/usui/RedAce_usui_v4/work_test/DRCX_create_graph.ipynb セル 4\u001b[0m line \u001b[0;36m1\n\u001b[0;32m----> <a href='vscode-notebook-cell:/Users/usui/RedAce_usui_v4/work_test/DRCX_create_graph.ipynb#W2sZmlsZQ%3D%3D?line=0'>1</a>\u001b[0m \u001b[39mimport\u001b[39;00m \u001b[39mgdal\u001b[39;00m\n",
      "\u001b[0;31mModuleNotFoundError\u001b[0m: No module named 'gdal'"
     ]
    }
   ],
   "source": [
    "import gdal"
   ]
  }
 ],
 "metadata": {
  "kernelspec": {
   "display_name": "Python 3",
   "language": "python",
   "name": "python3"
  },
  "language_info": {
   "codemirror_mode": {
    "name": "ipython",
    "version": 3
   },
   "file_extension": ".py",
   "mimetype": "text/x-python",
   "name": "python",
   "nbconvert_exporter": "python",
   "pygments_lexer": "ipython3",
   "version": "3.6.8"
  },
  "orig_nbformat": 4
 },
 "nbformat": 4,
 "nbformat_minor": 2
}
